{"errorMessage": "An error occurred (NoSuchBucket) when calling the PutObject operation: The specified bucket does not exist", "errorType": "NoSuchBucket", "requestId": "d6421890-b40a-4502-a393-41ad0d9a6666", "stackTrace": ["  File \"/var/task/app.py\", line 65, in handler\n    s3.put_object(Bucket=BUCKET, Key=filename, Body=body, ContentType=content_type)\n", "  File \"/var/lang/lib/python3.12/site-packages/botocore/client.py\", line 602, in _api_call\n    return self._make_api_call(operation_name, kwargs)\n", "  File \"/var/lang/lib/python3.12/site-packages/botocore/context.py\", line 123, in wrapper\n    return func(*args, **kwargs)\n", "  File \"/var/lang/lib/python3.12/site-packages/botocore/client.py\", line 1078, in _make_api_call\n    raise error_class(parsed_response, operation_name)\n"]}